[4.14959064 3.92058289]
[3.23362003 3.10309768]
[2.68720707 2.60369631]
[2.32700159 2.26938699]
[2.07323409 2.03133439]
[1.88581762 1.85414353]
[1.74246467 1.71780375]
[1.62981891 1.61016939]
[1.53939876 1.52344977]
[1.46556383 1.45242169]
[1.40441922 1.39345402]
[1.35318981 1.34394495]
[1.30984532 1.30198183]
[1.27286641 1.26612739]
[1.24109359 1.23528083]
[1.21362671 1.20858486]
[1.18975641 1.18536199]
[1.16891612 1.16506977]
[1.15064798 1.14726884]
[1.13457795 1.13159959]
[1.12039761 1.11776494]
[1.10785039 1.10551737]
[1.09672125 1.0946491 ]
[1.08682863 1.08498449]
[1.07801829 1.07637414]
[1.07015841 1.06869024]
[1.06313579 1.06182289]
[1.05685268 1.05567713]
[1.05122435 1.0501706 ]
[1.04617707 1.04523152]
[1.04164641 1.04079718]
[1.03757592 1.03681256]
[1.03391596 1.03322929]
[1.03062281 1.03000471]
[1.02765779 1.02710108]
[1.02498667 1.02448498]
/home/u4/nraviles/parallel_tests_rev/fig_functions.py:263: RuntimeWarning: invalid value encountered in double_scalars
  eff_r = cr*(1-y)*(1-(1+b*y)*np.exp(-b*y))/(y+(1-y)*(1-np.exp(-b)))*(b*y-1+np.exp(-b*y))/(b*y*(1-np.exp(-b*y))+cr*(1-(1+b*y)*np.exp(-b*y)))
0.8528387546539307
[0]
[1.91034571e-16]
[0.08376229]
[0.1971305]
[0.29171058]
[0.37205458]
[0.44119943]
[0.50128515]
[0.55388576]
[0.60019924]
[0.64116309]
[0.67752788]
[0.70990597]
[0.73880482]
[0.76465047]
[0.7878046]
[0.80857701]
[0.82723516]
[0.84401149]
[0.85910907]
[0.8727062]
[0.88496005]
[0.8960096]
[0.90597817]
[0.91497542]
[0.92309909]
[0.93043647]
[0.93706563]
[0.94305648]
[0.94847176]
[0.95336776]
[0.95779509]
[0.96179928]
[0.96542128]
[0.96869801]
[0.97166272]
joblib.externals.loky.process_executor._RemoteTraceback: 
"""
Traceback (most recent call last):
  File "/opt/ohpc/pub/apps/python/3.8.2/lib/python3.8/site-packages/joblib/externals/loky/process_executor.py", line 418, in _process_worker
    r = call_item()
  File "/opt/ohpc/pub/apps/python/3.8.2/lib/python3.8/site-packages/joblib/externals/loky/process_executor.py", line 272, in __call__
    return self.fn(*self.args, **self.kwargs)
  File "/opt/ohpc/pub/apps/python/3.8.2/lib/python3.8/site-packages/joblib/_parallel_backends.py", line 608, in __call__
    return self.func(*args, **kwargs)
  File "/opt/ohpc/pub/apps/python/3.8.2/lib/python3.8/site-packages/joblib/parallel.py", line 255, in __call__
    return [func(*args, **kwargs)
  File "/opt/ohpc/pub/apps/python/3.8.2/lib/python3.8/site-packages/joblib/parallel.py", line 255, in <listcomp>
    return [func(*args, **kwargs)
  File "/home/u4/nraviles/parallel_tests_rev/fig_functions.py", line 487, in modsimpop
    deltan = deltnplussim(mi,c,U)
  File "/home/u4/nraviles/parallel_tests_rev/fig_functions.py", line 320, in deltnplussim
    comp_wld =np.random.poisson(lam=l[0],size=[comp_U,1])
  File "mtrand.pyx", line 3554, in numpy.random.mtrand.RandomState.poisson
  File "_common.pyx", line 815, in numpy.random._common.disc
  File "_common.pyx", line 377, in numpy.random._common.check_constraint
ValueError: lam < 0 or lam is NaN
"""

The above exception was the direct cause of the following exception:

Traceback (most recent call last):
  File "HPC_Pfix_Simulation.py", line 97, in <module>
    element_run_abs = Parallel(n_jobs=-1)(delayed(myfun.modsimpop)(d_Inc,c_Inc,samp,parValue[parName['T']],parValue[parName['cr']],parValue[parName['b']],di[k*part:(k*part + 2)],parValue[parName['do']],((di[k*part]/di[k*part + 1])-1)/(di[k*part + 1]-1),d_max,yi_option) for k in range(subsamp)) #got rid of the minus 1
  File "/opt/ohpc/pub/apps/python/3.8.2/lib/python3.8/site-packages/joblib/parallel.py", line 1017, in __call__
    self.retrieve()
  File "/opt/ohpc/pub/apps/python/3.8.2/lib/python3.8/site-packages/joblib/parallel.py", line 909, in retrieve
    self._output.extend(job.get(timeout=self.timeout))
  File "/opt/ohpc/pub/apps/python/3.8.2/lib/python3.8/site-packages/joblib/_parallel_backends.py", line 562, in wrap_future_result
    return future.result(timeout=timeout)
  File "/opt/ohpc/pub/apps/python/3.8.2/lib/python3.8/concurrent/futures/_base.py", line 439, in result
    return self.__get_result()
  File "/opt/ohpc/pub/apps/python/3.8.2/lib/python3.8/concurrent/futures/_base.py", line 388, in __get_result
    raise self._exception
ValueError: lam < 0 or lam is NaN
Detailed performance metrics for this job will be available at https://metrics.hpc.arizona.edu/#job_viewer?action=show&realm=SUPREMM&resource_id=5&local_job_id=142186 by 8am on 2021/08/31.
